Traceback (most recent call last):
  File "/home/ubuntu/DE2-GithubAnalytics/consumers/main_repo_consumer.py", line 6, in <module>
    consumer = client.subscribe("MainGithubRepoTopic", "my-subscription")
  File "/usr/local/lib/python3.8/dist-packages/pulsar/__init__.py", line 803, in subscribe
    c._consumer = self._client.subscribe(topic, subscription_name, conf)
_pulsar.ConnectError: Pulsar error: ConnectError
Traceback (most recent call last):
  File "/home/ubuntu/DE2-GithubAnalytics/consumers/main_repo_consumer.py", line 6, in <module>
    consumer = client.subscribe("MainGithubRepoTopic", "my-subscription")
  File "/usr/local/lib/python3.8/dist-packages/pulsar/__init__.py", line 803, in subscribe
    c._consumer = self._client.subscribe(topic, subscription_name, conf)
_pulsar.ConnectError: Pulsar error: ConnectError
Traceback (most recent call last):
  File "/home/ubuntu/DE2-GithubAnalytics/consumers/main_repo_consumer.py", line 6, in <module>
    consumer = client.subscribe("MainGithubRepoTopic", "my-subscription")
  File "/usr/local/lib/python3.8/dist-packages/pulsar/__init__.py", line 803, in subscribe
    c._consumer = self._client.subscribe(topic, subscription_name, conf)
_pulsar.ConnectError: Pulsar error: ConnectError
Traceback (most recent call last):
  File "/home/ubuntu/DE2-GithubAnalytics/consumers/main_repo_consumer.py", line 6, in <module>
    consumer = client.subscribe("MainGithubRepoTopic", "my-subscription")
  File "/usr/local/lib/python3.8/dist-packages/pulsar/__init__.py", line 803, in subscribe
    c._consumer = self._client.subscribe(topic, subscription_name, conf)
_pulsar.ConsumerBusy: Pulsar error: ConsumerBusy
Traceback (most recent call last):
  File "/home/ubuntu/DE2-GithubAnalytics/consumers/main_repo_consumer.py", line 6, in <module>
    consumer = client.subscribe("MainGithubRepoTopic", "my-subscription")
  File "/usr/local/lib/python3.8/dist-packages/pulsar/__init__.py", line 803, in subscribe
    c._consumer = self._client.subscribe(topic, subscription_name, conf)
_pulsar.ConnectError: Pulsar error: ConnectError
Traceback (most recent call last):
  File "/home/ubuntu/DE2-GithubAnalytics/consumers/main_repo_consumer.py", line 6, in <module>
    consumer = client.subscribe("MainGithubRepoTopic", "my-subscription")
  File "/usr/local/lib/python3.8/dist-packages/pulsar/__init__.py", line 803, in subscribe
    c._consumer = self._client.subscribe(topic, subscription_name, conf)
_pulsar.ConsumerBusy: Pulsar error: ConsumerBusy
Traceback (most recent call last):
  File "/home/ubuntu/DE2-GithubAnalytics/consumers/main_repo_consumer.py", line 6, in <module>
    consumer = client.subscribe("MainGithubRepoTopic", "my-subscription")
  File "/usr/local/lib/python3.8/dist-packages/pulsar/__init__.py", line 803, in subscribe
    c._consumer = self._client.subscribe(topic, subscription_name, conf)
_pulsar.ConnectError: Pulsar error: ConnectError
Traceback (most recent call last):
  File "/home/ubuntu/DE2-GithubAnalytics/consumers/main_repo_consumer.py", line 6, in <module>
    consumer = client.subscribe("MainGithubRepoTopic", "my-subscription")
  File "/usr/local/lib/python3.8/dist-packages/pulsar/__init__.py", line 803, in subscribe
    c._consumer = self._client.subscribe(topic, subscription_name, conf)
_pulsar.ConsumerBusy: Pulsar error: ConsumerBusy
Traceback (most recent call last):
  File "/home/ubuntu/DE2-GithubAnalytics/consumers/main_repo_consumer.py", line 6, in <module>
    consumer = client.subscribe("MainGithubRepoTopic", "my-subscription")
  File "/usr/local/lib/python3.8/dist-packages/pulsar/__init__.py", line 803, in subscribe
    c._consumer = self._client.subscribe(topic, subscription_name, conf)
_pulsar.ConnectError: Pulsar error: ConnectError
Traceback (most recent call last):
  File "/home/ubuntu/DE2-GithubAnalytics/consumers/main_repo_consumer.py", line 6, in <module>
    consumer = client.subscribe("MainGithubRepoTopic", "my-subscription")
  File "/usr/local/lib/python3.8/dist-packages/pulsar/__init__.py", line 803, in subscribe
    c._consumer = self._client.subscribe(topic, subscription_name, conf)
_pulsar.ConsumerBusy: Pulsar error: ConsumerBusy
Traceback (most recent call last):
  File "/home/ubuntu/DE2-GithubAnalytics/consumers/main_repo_consumer.py", line 6, in <module>
    consumer = client.subscribe("MainGithubRepoTopic", "my-subscription")
  File "/usr/local/lib/python3.8/dist-packages/pulsar/__init__.py", line 803, in subscribe
    c._consumer = self._client.subscribe(topic, subscription_name, conf)
_pulsar.ConnectError: Pulsar error: ConnectError
Traceback (most recent call last):
  File "/home/ubuntu/DE2-GithubAnalytics/consumers/main_repo_consumer.py", line 6, in <module>
    consumer = client.subscribe("MainGithubRepoTopic", "my-subscription")
  File "/usr/local/lib/python3.8/dist-packages/pulsar/__init__.py", line 803, in subscribe
    c._consumer = self._client.subscribe(topic, subscription_name, conf)
_pulsar.ConsumerBusy: Pulsar error: ConsumerBusy
Traceback (most recent call last):
  File "/home/ubuntu/DE2-GithubAnalytics/consumers/main_repo_consumer.py", line 6, in <module>
    consumer = client.subscribe("MainGithubRepoTopic", "my-subscription")
  File "/usr/local/lib/python3.8/dist-packages/pulsar/__init__.py", line 803, in subscribe
    c._consumer = self._client.subscribe(topic, subscription_name, conf)
_pulsar.ConnectError: Pulsar error: ConnectError
Traceback (most recent call last):
  File "/home/ubuntu/DE2-GithubAnalytics/consumers/main_repo_consumer.py", line 6, in <module>
    consumer = client.subscribe("MainGithubRepoTopic", "my-subscription")
  File "/usr/local/lib/python3.8/dist-packages/pulsar/__init__.py", line 803, in subscribe
    c._consumer = self._client.subscribe(topic, subscription_name, conf)
_pulsar.ConsumerBusy: Pulsar error: ConsumerBusy
Traceback (most recent call last):
  File "/home/ubuntu/DE2-GithubAnalytics/consumers/main_repo_consumer.py", line 6, in <module>
    consumer = client.subscribe("MainGithubRepoTopic", "my-subscription")
  File "/usr/local/lib/python3.8/dist-packages/pulsar/__init__.py", line 803, in subscribe
    c._consumer = self._client.subscribe(topic, subscription_name, conf)
_pulsar.ConnectError: Pulsar error: ConnectError
Traceback (most recent call last):
  File "/home/ubuntu/DE2-GithubAnalytics/consumers/main_repo_consumer.py", line 6, in <module>
    consumer = client.subscribe("MainGithubRepoTopic", "my-subscription")
  File "/usr/local/lib/python3.8/dist-packages/pulsar/__init__.py", line 803, in subscribe
    c._consumer = self._client.subscribe(topic, subscription_name, conf)
_pulsar.ConnectError: Pulsar error: ConnectError
